<?xml version="1.0" encoding="UTF-8"?>
<testsuite errors="1" failures="0" file="unittest/loader.py" name="unittest.loader._FailedTest-20200626223259" skipped="0" tests="1" time="0.004" timestamp="2020-06-26T22:33:00">
	<testcase classname="unittest.loader._FailedTest" name="model_tests" time="0.004" timestamp="2020-06-26T22:33:00">
		<error message="Failed to import test module: model_tests
Traceback (most recent call last):
  File &quot;/usr/lib/python3.6/unittest/loader.py&quot;, line 153, in loadTestsFromName
    module = __import__(module_name)
  File &quot;/mnt/c/users/mahe/desktop/new folder/newproject/src/unittest/python/model_tests.py&quot;, line 10, in &lt;module&gt;
    import pandas as pd
ModuleNotFoundError: No module named 'pandas'
" type="ImportError">
<![CDATA[Traceback (most recent call last):
  File "/usr/lib/python3.6/unittest/case.py", line 59, in testPartExecutor
    yield
  File "/usr/lib/python3.6/unittest/case.py", line 605, in run
    testMethod()
  File "/usr/lib/python3.6/unittest/loader.py", line 34, in testFailure
    raise self._exception
ImportError: Failed to import test module: model_tests
Traceback (most recent call last):
  File "/usr/lib/python3.6/unittest/loader.py", line 153, in loadTestsFromName
    module = __import__(module_name)
  File "/mnt/c/users/mahe/desktop/new folder/newproject/src/unittest/python/model_tests.py", line 10, in <module>
    import pandas as pd
ModuleNotFoundError: No module named 'pandas'

]]>		</error>
		<system-out>
<![CDATA[]]>		</system-out>
		<system-err>
<![CDATA[]]>		</system-err>
	</testcase>
</testsuite>
